<?xml version="1.0" encoding="UTF-8"?>
<testng-results retried="1" ignored="0" total="7" passed="2" failed="3" skipped="1">
  <reporter-output>
  </reporter-output>
  <suite started-at="2024-07-20T13:50:54 PDT" name="Suite" finished-at="2024-07-20T13:51:55 PDT" duration-ms="61869">
    <groups>
      <group name="Sanity">
        <method signature="ErrorValidationsTest.loginErrorValidation()[pri:0, instance:techniqum.Selenium.tests.ErrorValidationsTest@6bbe85a8]" name="loginErrorValidation" class="techniqum.Selenium.tests.ErrorValidationsTest"/>
      </group> <!-- Sanity -->
      <group name="Purchase">
        <method signature="StandAloneTest2.submitOrder(java.util.HashMap)[pri:0, instance:techniqum.Selenium.tests.StandAloneTest2@130c12b7]" name="submitOrder" class="techniqum.Selenium.tests.StandAloneTest2"/>
        <method signature="StandAloneTest2.orderHistoryTest(java.util.HashMap)[pri:0, instance:techniqum.Selenium.tests.StandAloneTest2@130c12b7]" name="orderHistoryTest" class="techniqum.Selenium.tests.StandAloneTest2"/>
      </group> <!-- Purchase -->
    </groups>
    <test started-at="2024-07-20T13:50:54 PDT" name="Submit Order Test" finished-at="2024-07-20T13:51:39 PDT" duration-ms="45639">
      <class name="techniqum.Selenium.tests.StandAloneTest2">
        <test-method is-config="true" signature="launchApplication()[pri:0, instance:techniqum.Selenium.tests.StandAloneTest2@130c12b7]" started-at="2024-07-20T13:50:54 PDT" name="launchApplication" finished-at="2024-07-20T13:50:59 PDT" duration-ms="4969" status="PASS">
          <reporter-output>
          </reporter-output>
        </test-method> <!-- launchApplication -->
        <test-method signature="submitOrder(java.util.HashMap)[pri:0, instance:techniqum.Selenium.tests.StandAloneTest2@130c12b7]" started-at="2024-07-20T13:50:59 PDT" name="submitOrder" data-provider="getData" finished-at="2024-07-20T13:51:08 PDT" duration-ms="9268" status="PASS">
          <params>
            <param index="0">
              <value>
                <![CDATA[{password=Kokokivi123, product=ZARA COAT 3, email=kaskhelmet22@gmail.com}]]>
              </value>
            </param>
          </params>
          <reporter-output>
          </reporter-output>
        </test-method> <!-- submitOrder -->
        <test-method is-config="true" signature="tearDown()[pri:0, instance:techniqum.Selenium.tests.StandAloneTest2@130c12b7]" started-at="2024-07-20T13:51:08 PDT" name="tearDown" finished-at="2024-07-20T13:51:08 PDT" duration-ms="107" status="PASS">
          <reporter-output>
          </reporter-output>
        </test-method> <!-- tearDown -->
        <test-method is-config="true" signature="launchApplication()[pri:0, instance:techniqum.Selenium.tests.StandAloneTest2@130c12b7]" started-at="2024-07-20T13:51:08 PDT" name="launchApplication" finished-at="2024-07-20T13:51:12 PDT" duration-ms="4223" status="PASS">
          <reporter-output>
          </reporter-output>
        </test-method> <!-- launchApplication -->
        <test-method signature="submitOrder(java.util.HashMap)[pri:0, instance:techniqum.Selenium.tests.StandAloneTest2@130c12b7]" started-at="2024-07-20T13:51:12 PDT" name="submitOrder" data-provider="getData" finished-at="2024-07-20T13:51:39 PDT" duration-ms="26782" status="FAIL">
          <params>
            <param index="0">
              <value>
                <![CDATA[{password=kqa1erb_qdc7UPE-jab, product=ADIDAS ORIGINAL, email=kantokaryb@gmail.com}]]>
              </value>
            </param>
          </params>
          <exception class="java.lang.AssertionError">
            <message>
              <![CDATA[expected [true] but found [false]]]>
            </message>
            <full-stacktrace>
              <![CDATA[java.lang.AssertionError: expected [true] but found [false]
at org.testng.Assert.fail(Assert.java:99)
at org.testng.Assert.failNotEquals(Assert.java:1037)
at org.testng.Assert.assertTrue(Assert.java:45)
at org.testng.Assert.assertTrue(Assert.java:55)
at techniqum.Selenium.tests.StandAloneTest2.submitOrder(StandAloneTest2.java:33)
at java.base/jdk.internal.reflect.DirectMethodHandleAccessor.invoke(DirectMethodHandleAccessor.java:103)
at java.base/java.lang.reflect.Method.invoke(Method.java:580)
at org.testng.internal.MethodInvocationHelper.invokeMethod(MethodInvocationHelper.java:133)
at org.testng.internal.TestInvoker.invokeMethod(TestInvoker.java:598)
at org.testng.internal.TestInvoker.invokeTestMethod(TestInvoker.java:173)
at org.testng.internal.MethodRunner.runInSequence(MethodRunner.java:46)
at org.testng.internal.TestInvoker$MethodInvocationAgent.invoke(TestInvoker.java:824)
at org.testng.internal.TestInvoker.invokeTestMethods(TestInvoker.java:146)
at org.testng.internal.TestMethodWorker.invokeTestMethods(TestMethodWorker.java:146)
at org.testng.internal.TestMethodWorker.run(TestMethodWorker.java:128)
at java.base/java.util.ArrayList.forEach(ArrayList.java:1596)
at org.testng.TestRunner.privateRun(TestRunner.java:794)
at org.testng.TestRunner.run(TestRunner.java:596)
at org.testng.SuiteRunner.runTest(SuiteRunner.java:377)
at org.testng.SuiteRunner.access$000(SuiteRunner.java:28)
at org.testng.SuiteRunner$SuiteWorker.run(SuiteRunner.java:418)
at org.testng.internal.thread.ThreadUtil.lambda$execute$0(ThreadUtil.java:64)
at java.base/java.util.concurrent.FutureTask.run(FutureTask.java:317)
at java.base/java.util.concurrent.ThreadPoolExecutor.runWorker(ThreadPoolExecutor.java:1144)
at java.base/java.util.concurrent.ThreadPoolExecutor$Worker.run(ThreadPoolExecutor.java:642)
at java.base/java.lang.Thread.run(Thread.java:1583)
]]>
            </full-stacktrace>
          </exception> <!-- java.lang.AssertionError -->
          <reporter-output>
          </reporter-output>
        </test-method> <!-- submitOrder -->
        <test-method is-config="true" signature="tearDown()[pri:0, instance:techniqum.Selenium.tests.StandAloneTest2@130c12b7]" started-at="2024-07-20T13:51:39 PDT" name="tearDown" finished-at="2024-07-20T13:51:39 PDT" duration-ms="81" status="PASS">
          <reporter-output>
          </reporter-output>
        </test-method> <!-- tearDown -->
        <test-method signature="orderHistoryTest(java.util.HashMap)[pri:0, instance:techniqum.Selenium.tests.StandAloneTest2@130c12b7]" started-at="2024-07-20T13:51:39 PDT" name="orderHistoryTest" finished-at="2024-07-20T13:51:39 PDT" depends-on-methods="techniqum.Selenium.tests.StandAloneTest2.submitOrder" duration-ms="0" status="SKIP">
          <exception class="java.lang.Throwable">
            <message>
              <![CDATA[Method StandAloneTest2.orderHistoryTest(java.util.HashMap)[pri:0, instance:techniqum.Selenium.tests.StandAloneTest2@130c12b7] depends on not successfully finished methods]]>
            </message>
            <full-stacktrace>
              <![CDATA[java.lang.Throwable: Method StandAloneTest2.orderHistoryTest(java.util.HashMap)[pri:0, instance:techniqum.Selenium.tests.StandAloneTest2@130c12b7] depends on not successfully finished methods
at org.testng.internal.TestInvoker.invokeTestMethods(TestInvoker.java:102)
at org.testng.internal.TestMethodWorker.invokeTestMethods(TestMethodWorker.java:146)
at org.testng.internal.TestMethodWorker.run(TestMethodWorker.java:128)
at java.base/java.util.ArrayList.forEach(ArrayList.java:1596)
at org.testng.TestRunner.privateRun(TestRunner.java:794)
at org.testng.TestRunner.run(TestRunner.java:596)
at org.testng.SuiteRunner.runTest(SuiteRunner.java:377)
at org.testng.SuiteRunner.access$000(SuiteRunner.java:28)
at org.testng.SuiteRunner$SuiteWorker.run(SuiteRunner.java:418)
at org.testng.internal.thread.ThreadUtil.lambda$execute$0(ThreadUtil.java:64)
at java.base/java.util.concurrent.FutureTask.run(FutureTask.java:317)
at java.base/java.util.concurrent.ThreadPoolExecutor.runWorker(ThreadPoolExecutor.java:1144)
at java.base/java.util.concurrent.ThreadPoolExecutor$Worker.run(ThreadPoolExecutor.java:642)
at java.base/java.lang.Thread.run(Thread.java:1583)
]]>
            </full-stacktrace>
          </exception> <!-- java.lang.Throwable -->
          <reporter-output>
          </reporter-output>
        </test-method> <!-- orderHistoryTest -->
      </class> <!-- techniqum.Selenium.tests.StandAloneTest2 -->
    </test> <!-- Submit Order Test -->
    <test started-at="2024-07-20T13:50:54 PDT" name="Error Validations Test" finished-at="2024-07-20T13:51:55 PDT" duration-ms="61869">
      <class name="techniqum.Selenium.tests.ErrorValidationsTest">
        <test-method is-config="true" signature="launchApplication()[pri:0, instance:techniqum.Selenium.tests.ErrorValidationsTest@6bbe85a8]" started-at="2024-07-20T13:50:54 PDT" name="launchApplication" finished-at="2024-07-20T13:50:59 PDT" duration-ms="5015" status="PASS">
          <reporter-output>
          </reporter-output>
        </test-method> <!-- launchApplication -->
        <test-method signature="checkOutErrorValidation()[pri:0, instance:techniqum.Selenium.tests.ErrorValidationsTest@6bbe85a8]" started-at="2024-07-20T13:50:59 PDT" name="checkOutErrorValidation" finished-at="2024-07-20T13:51:16 PDT" duration-ms="17619" status="FAIL">
          <exception class="java.lang.AssertionError">
            <message>
              <![CDATA[expected [true] but found [false]]]>
            </message>
            <full-stacktrace>
              <![CDATA[java.lang.AssertionError: expected [true] but found [false]
at org.testng.Assert.fail(Assert.java:99)
at org.testng.Assert.failNotEquals(Assert.java:1037)
at org.testng.Assert.assertTrue(Assert.java:45)
at org.testng.Assert.assertTrue(Assert.java:55)
at techniqum.Selenium.tests.ErrorValidationsTest.checkOutErrorValidation(ErrorValidationsTest.java:74)
at java.base/jdk.internal.reflect.DirectMethodHandleAccessor.invoke(DirectMethodHandleAccessor.java:103)
at java.base/java.lang.reflect.Method.invoke(Method.java:580)
at org.testng.internal.MethodInvocationHelper.invokeMethod(MethodInvocationHelper.java:133)
at org.testng.internal.TestInvoker.invokeMethod(TestInvoker.java:598)
at org.testng.internal.TestInvoker.invokeTestMethod(TestInvoker.java:173)
at org.testng.internal.MethodRunner.runInSequence(MethodRunner.java:46)
at org.testng.internal.TestInvoker$MethodInvocationAgent.invoke(TestInvoker.java:824)
at org.testng.internal.TestInvoker.invokeTestMethods(TestInvoker.java:146)
at org.testng.internal.TestMethodWorker.invokeTestMethods(TestMethodWorker.java:146)
at org.testng.internal.TestMethodWorker.run(TestMethodWorker.java:128)
at java.base/java.util.ArrayList.forEach(ArrayList.java:1596)
at org.testng.TestRunner.privateRun(TestRunner.java:794)
at org.testng.TestRunner.run(TestRunner.java:596)
at org.testng.SuiteRunner.runTest(SuiteRunner.java:377)
at org.testng.SuiteRunner.access$000(SuiteRunner.java:28)
at org.testng.SuiteRunner$SuiteWorker.run(SuiteRunner.java:418)
at org.testng.internal.thread.ThreadUtil.lambda$execute$0(ThreadUtil.java:64)
at java.base/java.util.concurrent.FutureTask.run(FutureTask.java:317)
at java.base/java.util.concurrent.ThreadPoolExecutor.runWorker(ThreadPoolExecutor.java:1144)
at java.base/java.util.concurrent.ThreadPoolExecutor$Worker.run(ThreadPoolExecutor.java:642)
at java.base/java.lang.Thread.run(Thread.java:1583)
]]>
            </full-stacktrace>
          </exception> <!-- java.lang.AssertionError -->
          <reporter-output>
          </reporter-output>
        </test-method> <!-- checkOutErrorValidation -->
        <test-method is-config="true" signature="tearDown()[pri:0, instance:techniqum.Selenium.tests.ErrorValidationsTest@6bbe85a8]" started-at="2024-07-20T13:51:16 PDT" name="tearDown" finished-at="2024-07-20T13:51:16 PDT" duration-ms="108" status="PASS">
          <reporter-output>
          </reporter-output>
        </test-method> <!-- tearDown -->
        <test-method is-config="true" signature="launchApplication()[pri:0, instance:techniqum.Selenium.tests.ErrorValidationsTest@6bbe85a8]" started-at="2024-07-20T13:51:16 PDT" name="launchApplication" finished-at="2024-07-20T13:51:21 PDT" duration-ms="4181" status="PASS">
          <reporter-output>
          </reporter-output>
        </test-method> <!-- launchApplication -->
        <test-method retried="true" signature="loginErrorValidation()[pri:0, instance:techniqum.Selenium.tests.ErrorValidationsTest@6bbe85a8]" started-at="2024-07-20T13:51:21 PDT" name="loginErrorValidation" finished-at="2024-07-20T13:51:21 PDT" duration-ms="536" status="SKIP">
          <exception class="java.lang.AssertionError">
            <message>
              <![CDATA[expected [Login Successfully] but found [Incorrect email or password.]]]>
            </message>
            <full-stacktrace>
              <![CDATA[java.lang.AssertionError: expected [Login Successfully] but found [Incorrect email or password.]
at org.testng.Assert.fail(Assert.java:99)
at org.testng.Assert.failNotEquals(Assert.java:1037)
at org.testng.Assert.assertEqualsImpl(Assert.java:140)
at org.testng.Assert.assertEquals(Assert.java:122)
at org.testng.Assert.assertEquals(Assert.java:629)
at org.testng.Assert.assertEquals(Assert.java:639)
at techniqum.Selenium.tests.ErrorValidationsTest.loginErrorValidation(ErrorValidationsTest.java:31)
at java.base/jdk.internal.reflect.DirectMethodHandleAccessor.invoke(DirectMethodHandleAccessor.java:103)
at java.base/java.lang.reflect.Method.invoke(Method.java:580)
at org.testng.internal.MethodInvocationHelper.invokeMethod(MethodInvocationHelper.java:133)
at org.testng.internal.TestInvoker.invokeMethod(TestInvoker.java:598)
at org.testng.internal.TestInvoker.invokeTestMethod(TestInvoker.java:173)
at org.testng.internal.MethodRunner.runInSequence(MethodRunner.java:46)
at org.testng.internal.TestInvoker$MethodInvocationAgent.invoke(TestInvoker.java:824)
at org.testng.internal.TestInvoker.invokeTestMethods(TestInvoker.java:146)
at org.testng.internal.TestMethodWorker.invokeTestMethods(TestMethodWorker.java:146)
at org.testng.internal.TestMethodWorker.run(TestMethodWorker.java:128)
at java.base/java.util.ArrayList.forEach(ArrayList.java:1596)
at org.testng.TestRunner.privateRun(TestRunner.java:794)
at org.testng.TestRunner.run(TestRunner.java:596)
at org.testng.SuiteRunner.runTest(SuiteRunner.java:377)
at org.testng.SuiteRunner.access$000(SuiteRunner.java:28)
at org.testng.SuiteRunner$SuiteWorker.run(SuiteRunner.java:418)
at org.testng.internal.thread.ThreadUtil.lambda$execute$0(ThreadUtil.java:64)
at java.base/java.util.concurrent.FutureTask.run(FutureTask.java:317)
at java.base/java.util.concurrent.ThreadPoolExecutor.runWorker(ThreadPoolExecutor.java:1144)
at java.base/java.util.concurrent.ThreadPoolExecutor$Worker.run(ThreadPoolExecutor.java:642)
at java.base/java.lang.Thread.run(Thread.java:1583)
]]>
            </full-stacktrace>
          </exception> <!-- java.lang.AssertionError -->
          <reporter-output>
          </reporter-output>
        </test-method> <!-- loginErrorValidation -->
        <test-method is-config="true" signature="tearDown()[pri:0, instance:techniqum.Selenium.tests.ErrorValidationsTest@6bbe85a8]" started-at="2024-07-20T13:51:21 PDT" name="tearDown" finished-at="2024-07-20T13:51:21 PDT" duration-ms="82" status="PASS">
          <reporter-output>
          </reporter-output>
        </test-method> <!-- tearDown -->
        <test-method is-config="true" signature="launchApplication()[pri:0, instance:techniqum.Selenium.tests.ErrorValidationsTest@6bbe85a8]" started-at="2024-07-20T13:51:21 PDT" name="launchApplication" finished-at="2024-07-20T13:51:25 PDT" duration-ms="4144" status="PASS">
          <reporter-output>
          </reporter-output>
        </test-method> <!-- launchApplication -->
        <test-method signature="loginErrorValidation()[pri:0, instance:techniqum.Selenium.tests.ErrorValidationsTest@6bbe85a8]" started-at="2024-07-20T13:51:25 PDT" name="loginErrorValidation" finished-at="2024-07-20T13:51:26 PDT" duration-ms="534" status="FAIL">
          <exception class="java.lang.AssertionError">
            <message>
              <![CDATA[expected [Login Successfully] but found [Incorrect email or password.]]]>
            </message>
            <full-stacktrace>
              <![CDATA[java.lang.AssertionError: expected [Login Successfully] but found [Incorrect email or password.]
at org.testng.Assert.fail(Assert.java:99)
at org.testng.Assert.failNotEquals(Assert.java:1037)
at org.testng.Assert.assertEqualsImpl(Assert.java:140)
at org.testng.Assert.assertEquals(Assert.java:122)
at org.testng.Assert.assertEquals(Assert.java:629)
at org.testng.Assert.assertEquals(Assert.java:639)
at techniqum.Selenium.tests.ErrorValidationsTest.loginErrorValidation(ErrorValidationsTest.java:31)
at java.base/jdk.internal.reflect.DirectMethodHandleAccessor.invoke(DirectMethodHandleAccessor.java:103)
at java.base/java.lang.reflect.Method.invoke(Method.java:580)
at org.testng.internal.MethodInvocationHelper.invokeMethod(MethodInvocationHelper.java:133)
at org.testng.internal.TestInvoker.invokeMethod(TestInvoker.java:598)
at org.testng.internal.TestInvoker.retryFailed(TestInvoker.java:213)
at org.testng.internal.MethodRunner.runInSequence(MethodRunner.java:58)
at org.testng.internal.TestInvoker$MethodInvocationAgent.invoke(TestInvoker.java:824)
at org.testng.internal.TestInvoker.invokeTestMethods(TestInvoker.java:146)
at org.testng.internal.TestMethodWorker.invokeTestMethods(TestMethodWorker.java:146)
at org.testng.internal.TestMethodWorker.run(TestMethodWorker.java:128)
at java.base/java.util.ArrayList.forEach(ArrayList.java:1596)
at org.testng.TestRunner.privateRun(TestRunner.java:794)
at org.testng.TestRunner.run(TestRunner.java:596)
at org.testng.SuiteRunner.runTest(SuiteRunner.java:377)
at org.testng.SuiteRunner.access$000(SuiteRunner.java:28)
at org.testng.SuiteRunner$SuiteWorker.run(SuiteRunner.java:418)
at org.testng.internal.thread.ThreadUtil.lambda$execute$0(ThreadUtil.java:64)
at java.base/java.util.concurrent.FutureTask.run(FutureTask.java:317)
at java.base/java.util.concurrent.ThreadPoolExecutor.runWorker(ThreadPoolExecutor.java:1144)
at java.base/java.util.concurrent.ThreadPoolExecutor$Worker.run(ThreadPoolExecutor.java:642)
at java.base/java.lang.Thread.run(Thread.java:1583)
]]>
            </full-stacktrace>
          </exception> <!-- java.lang.AssertionError -->
          <reporter-output>
          </reporter-output>
        </test-method> <!-- loginErrorValidation -->
        <test-method is-config="true" signature="tearDown()[pri:0, instance:techniqum.Selenium.tests.ErrorValidationsTest@6bbe85a8]" started-at="2024-07-20T13:51:26 PDT" name="tearDown" finished-at="2024-07-20T13:51:26 PDT" duration-ms="83" status="PASS">
          <reporter-output>
          </reporter-output>
        </test-method> <!-- tearDown -->
        <test-method is-config="true" signature="launchApplication()[pri:0, instance:techniqum.Selenium.tests.ErrorValidationsTest@6bbe85a8]" started-at="2024-07-20T13:51:26 PDT" name="launchApplication" finished-at="2024-07-20T13:51:30 PDT" duration-ms="4104" status="PASS">
          <reporter-output>
          </reporter-output>
        </test-method> <!-- launchApplication -->
        <test-method signature="productErrorValidation()[pri:0, instance:techniqum.Selenium.tests.ErrorValidationsTest@6bbe85a8]" started-at="2024-07-20T13:51:30 PDT" name="productErrorValidation" finished-at="2024-07-20T13:51:55 PDT" duration-ms="25108" status="PASS">
          <reporter-output>
          </reporter-output>
        </test-method> <!-- productErrorValidation -->
        <test-method is-config="true" signature="tearDown()[pri:0, instance:techniqum.Selenium.tests.ErrorValidationsTest@6bbe85a8]" started-at="2024-07-20T13:51:55 PDT" name="tearDown" finished-at="2024-07-20T13:51:55 PDT" duration-ms="110" status="PASS">
          <reporter-output>
          </reporter-output>
        </test-method> <!-- tearDown -->
      </class> <!-- techniqum.Selenium.tests.ErrorValidationsTest -->
    </test> <!-- Error Validations Test -->
  </suite> <!-- Suite -->
</testng-results>
